<?xml version="1.0" encoding="UTF-8"?>
<!-- Generated by org.testng.reporters.JUnitReportReporter -->
<testsuite hostname="pay1lap-71-PC" name="pay1_distributor.SalesmanTransfer" tests="9" failures="2" timestamp="16 May 2017 21:50:35 GMT" time="135.474" errors="0">
  <testcase name="verifySalesmanBalance" time="1.537" classname="pay1_distributor.SalesmanTransfer"/>
  <testcase name="accHistory1" time="22.391" classname="pay1_distributor.SalesmanTransfer">
    <failure type="java.lang.AssertionError" message="Error while confirming pullback transaction">
      <![CDATA[java.lang.AssertionError: Error while confirming pullback transaction
	at org.testng.Assert.fail(Assert.java:94)
	at pay1_distributor.SalesmanTransfer.accHistory1(SalesmanTransfer.java:422)
	at sun.reflect.NativeMethodAccessorImpl.invoke0(Native Method)
	at sun.reflect.NativeMethodAccessorImpl.invoke(NativeMethodAccessorImpl.java:62)
	at sun.reflect.DelegatingMethodAccessorImpl.invoke(DelegatingMethodAccessorImpl.java:43)
	at java.lang.reflect.Method.invoke(Method.java:498)
	at org.testng.internal.MethodInvocationHelper.invokeMethod(MethodInvocationHelper.java:85)
	at org.testng.internal.Invoker.invokeMethod(Invoker.java:639)
	at org.testng.internal.Invoker.retryFailed(Invoker.java:963)
	at org.testng.internal.Invoker.invokeTestMethods(Invoker.java:1142)
	at org.testng.internal.TestMethodWorker.invokeTestMethods(TestMethodWorker.java:125)
	at org.testng.internal.TestMethodWorker.run(TestMethodWorker.java:108)
	at org.testng.TestRunner.privateRun(TestRunner.java:774)
	at org.testng.TestRunner.run(TestRunner.java:624)
	at org.testng.SuiteRunner.runTest(SuiteRunner.java:359)
	at org.testng.SuiteRunner.runSequentially(SuiteRunner.java:354)
	at org.testng.SuiteRunner.privateRun(SuiteRunner.java:312)
	at org.testng.SuiteRunner.run(SuiteRunner.java:261)
	at org.testng.SuiteRunnerWorker.runSuite(SuiteRunnerWorker.java:52)
	at org.testng.SuiteRunnerWorker.run(SuiteRunnerWorker.java:86)
	at org.testng.TestNG.runSuitesSequentially(TestNG.java:1215)
	at org.testng.TestNG.runSuitesLocally(TestNG.java:1140)
	at org.testng.TestNG.run(TestNG.java:1048)
	at org.testng.remote.AbstractRemoteTestNG.run(AbstractRemoteTestNG.java:132)
	at org.testng.remote.RemoteTestNG.initAndRun(RemoteTestNG.java:236)
	at org.testng.remote.RemoteTestNG.main(RemoteTestNG.java:81)
]]>
    </failure>
  </testcase> <!-- accHistory1 -->
  <testcase name="getSalesmanBalance" time="3.389" classname="pay1_distributor.SalesmanTransfer"/>
  <testcase name="accHistory1" time="18.902" classname="pay1_distributor.SalesmanTransfer">
    <failure type="java.lang.AssertionError" message="Error while confirming pullback transaction">
      <![CDATA[java.lang.AssertionError: Error while confirming pullback transaction
	at org.testng.Assert.fail(Assert.java:94)
	at pay1_distributor.SalesmanTransfer.accHistory1(SalesmanTransfer.java:422)
	at sun.reflect.NativeMethodAccessorImpl.invoke0(Native Method)
	at sun.reflect.NativeMethodAccessorImpl.invoke(NativeMethodAccessorImpl.java:62)
	at sun.reflect.DelegatingMethodAccessorImpl.invoke(DelegatingMethodAccessorImpl.java:43)
	at java.lang.reflect.Method.invoke(Method.java:498)
	at org.testng.internal.MethodInvocationHelper.invokeMethod(MethodInvocationHelper.java:85)
	at org.testng.internal.Invoker.invokeMethod(Invoker.java:639)
	at org.testng.internal.Invoker.invokeTestMethod(Invoker.java:816)
	at org.testng.internal.Invoker.invokeTestMethods(Invoker.java:1124)
	at org.testng.internal.TestMethodWorker.invokeTestMethods(TestMethodWorker.java:125)
	at org.testng.internal.TestMethodWorker.run(TestMethodWorker.java:108)
	at org.testng.TestRunner.privateRun(TestRunner.java:774)
	at org.testng.TestRunner.run(TestRunner.java:624)
	at org.testng.SuiteRunner.runTest(SuiteRunner.java:359)
	at org.testng.SuiteRunner.runSequentially(SuiteRunner.java:354)
	at org.testng.SuiteRunner.privateRun(SuiteRunner.java:312)
	at org.testng.SuiteRunner.run(SuiteRunner.java:261)
	at org.testng.SuiteRunnerWorker.runSuite(SuiteRunnerWorker.java:52)
	at org.testng.SuiteRunnerWorker.run(SuiteRunnerWorker.java:86)
	at org.testng.TestNG.runSuitesSequentially(TestNG.java:1215)
	at org.testng.TestNG.runSuitesLocally(TestNG.java:1140)
	at org.testng.TestNG.run(TestNG.java:1048)
	at org.testng.remote.AbstractRemoteTestNG.run(AbstractRemoteTestNG.java:132)
	at org.testng.remote.RemoteTestNG.initAndRun(RemoteTestNG.java:236)
	at org.testng.remote.RemoteTestNG.main(RemoteTestNG.java:81)
]]>
    </failure>
  </testcase> <!-- accHistory1 -->
  <testcase name="spullback" time="11.061" classname="pay1_distributor.SalesmanTransfer"/>
  <testcase name="stransfer" time="36.601" classname="pay1_distributor.SalesmanTransfer"/>
  <testcase name="salesman_listchanges" time="33.158" classname="pay1_distributor.SalesmanTransfer"/>
  <testcase name="lastTransactions" time="3.628" classname="pay1_distributor.SalesmanTransfer"/>
  <testcase name="mainReport" time="4.807" classname="pay1_distributor.SalesmanTransfer"/>
</testsuite> <!-- pay1_distributor.SalesmanTransfer -->
